[2022-06-27 03:50:58,315: INFO/MainProcess] Connected to redis://redis:6379/0
[2022-06-27 03:50:58,335: INFO/MainProcess] mingle: searching for neighbors
[2022-06-27 03:50:59,369: INFO/MainProcess] mingle: all alone
[2022-06-27 03:50:59,383: INFO/MainProcess] celery@b73c8cac6a71 ready.
[2022-06-27 03:51:03,222: INFO/MainProcess] Events of group {task} enabled by remote.
[2022-06-27 03:53:23,698: INFO/MainProcess] Received task: create_task[53807a93-5336-4ec9-9742-d570ad6ef8f9]  
[2022-06-27 03:53:23,708: INFO/ForkPoolWorker-3] Task create_task[53807a93-5336-4ec9-9742-d570ad6ef8f9] succeeded in 0.004284272999996119s: True
[2022-06-27 03:53:59,076: INFO/MainProcess] Received task: create_task[f6f4abf2-bed8-4264-a7d9-499c987d3d5c]  
[2022-06-27 03:54:09,063: INFO/ForkPoolWorker-3] Task create_task[f6f4abf2-bed8-4264-a7d9-499c987d3d5c] succeeded in 10.004591643999959s: True
[2022-06-27 04:00:13,785: ERROR/MainProcess] consumer: Cannot connect to amqp://myuser:**@127.0.0.1:5672//: [Errno 111] Connection refused.
Trying again in 2.00 seconds... (1/100)

[2022-06-27 04:00:15,797: ERROR/MainProcess] consumer: Cannot connect to amqp://myuser:**@127.0.0.1:5672//: [Errno 111] Connection refused.
Trying again in 4.00 seconds... (2/100)

[2022-06-27 04:00:19,814: ERROR/MainProcess] consumer: Cannot connect to amqp://myuser:**@127.0.0.1:5672//: [Errno 111] Connection refused.
Trying again in 6.00 seconds... (3/100)

[2022-06-27 04:00:25,833: ERROR/MainProcess] consumer: Cannot connect to amqp://myuser:**@127.0.0.1:5672//: [Errno 111] Connection refused.
Trying again in 8.00 seconds... (4/100)

[2022-06-27 04:00:33,838: ERROR/MainProcess] consumer: Cannot connect to amqp://myuser:**@127.0.0.1:5672//: [Errno 111] Connection refused.
Trying again in 10.00 seconds... (5/100)

[2022-06-27 04:00:43,872: ERROR/MainProcess] consumer: Cannot connect to amqp://myuser:**@127.0.0.1:5672//: [Errno 111] Connection refused.
Trying again in 12.00 seconds... (6/100)

[2022-06-27 04:00:55,914: ERROR/MainProcess] consumer: Cannot connect to amqp://myuser:**@127.0.0.1:5672//: [Errno 111] Connection refused.
Trying again in 14.00 seconds... (7/100)

[2022-06-27 04:01:09,946: ERROR/MainProcess] consumer: Cannot connect to amqp://myuser:**@127.0.0.1:5672//: [Errno 111] Connection refused.
Trying again in 16.00 seconds... (8/100)

[2022-06-27 04:03:02,368: ERROR/MainProcess] consumer: Cannot connect to amqp://myuser:**@127.0.0.1:5672//: [Errno 111] Connection refused.
Trying again in 2.00 seconds... (1/100)

[2022-06-27 04:03:04,377: ERROR/MainProcess] consumer: Cannot connect to amqp://myuser:**@127.0.0.1:5672//: [Errno 111] Connection refused.
Trying again in 4.00 seconds... (2/100)

[2022-06-27 04:03:08,388: ERROR/MainProcess] consumer: Cannot connect to amqp://myuser:**@127.0.0.1:5672//: [Errno 111] Connection refused.
Trying again in 6.00 seconds... (3/100)

[2022-06-27 04:03:14,409: ERROR/MainProcess] consumer: Cannot connect to amqp://myuser:**@127.0.0.1:5672//: [Errno 111] Connection refused.
Trying again in 8.00 seconds... (4/100)

[2022-06-27 04:03:22,443: ERROR/MainProcess] consumer: Cannot connect to amqp://myuser:**@127.0.0.1:5672//: [Errno 111] Connection refused.
Trying again in 10.00 seconds... (5/100)

[2022-06-27 04:03:32,458: ERROR/MainProcess] consumer: Cannot connect to amqp://myuser:**@127.0.0.1:5672//: [Errno 111] Connection refused.
Trying again in 12.00 seconds... (6/100)

[2022-06-27 04:03:44,495: ERROR/MainProcess] consumer: Cannot connect to amqp://myuser:**@127.0.0.1:5672//: [Errno 111] Connection refused.
Trying again in 14.00 seconds... (7/100)

[2022-06-27 04:03:58,542: ERROR/MainProcess] consumer: Cannot connect to amqp://myuser:**@127.0.0.1:5672//: [Errno 111] Connection refused.
Trying again in 16.00 seconds... (8/100)

[2022-06-27 04:04:14,563: ERROR/MainProcess] consumer: Cannot connect to amqp://myuser:**@127.0.0.1:5672//: [Errno 111] Connection refused.
Trying again in 18.00 seconds... (9/100)

[2022-06-27 04:04:32,588: ERROR/MainProcess] consumer: Cannot connect to amqp://myuser:**@127.0.0.1:5672//: [Errno 111] Connection refused.
Trying again in 20.00 seconds... (10/100)

[2022-06-27 04:04:52,645: ERROR/MainProcess] consumer: Cannot connect to amqp://myuser:**@127.0.0.1:5672//: [Errno 111] Connection refused.
Trying again in 22.00 seconds... (11/100)

[2022-06-27 04:05:14,699: ERROR/MainProcess] consumer: Cannot connect to amqp://myuser:**@127.0.0.1:5672//: [Errno 111] Connection refused.
Trying again in 24.00 seconds... (12/100)

[2022-06-27 04:05:29,106: ERROR/MainProcess] consumer: Cannot connect to amqp://myuser:**@127.0.0.1:5672//: [Errno 111] Connection refused.
Trying again in 2.00 seconds... (1/100)

[2022-06-27 04:05:31,123: ERROR/MainProcess] consumer: Cannot connect to amqp://myuser:**@127.0.0.1:5672//: [Errno 111] Connection refused.
Trying again in 4.00 seconds... (2/100)

[2022-06-27 04:05:35,144: ERROR/MainProcess] consumer: Cannot connect to amqp://myuser:**@127.0.0.1:5672//: [Errno 111] Connection refused.
Trying again in 6.00 seconds... (3/100)

[2022-06-27 04:05:41,165: ERROR/MainProcess] consumer: Cannot connect to amqp://myuser:**@127.0.0.1:5672//: [Errno 111] Connection refused.
Trying again in 8.00 seconds... (4/100)

[2022-06-27 04:05:49,201: ERROR/MainProcess] consumer: Cannot connect to amqp://myuser:**@127.0.0.1:5672//: [Errno 111] Connection refused.
Trying again in 10.00 seconds... (5/100)

[2022-06-27 04:05:59,218: ERROR/MainProcess] consumer: Cannot connect to amqp://myuser:**@127.0.0.1:5672//: [Errno 111] Connection refused.
Trying again in 12.00 seconds... (6/100)

[2022-06-27 04:06:11,263: ERROR/MainProcess] consumer: Cannot connect to amqp://myuser:**@127.0.0.1:5672//: [Errno 111] Connection refused.
Trying again in 14.00 seconds... (7/100)

[2022-06-27 04:06:25,318: ERROR/MainProcess] consumer: Cannot connect to amqp://myuser:**@127.0.0.1:5672//: [Errno 111] Connection refused.
Trying again in 16.00 seconds... (8/100)

[2022-06-27 04:06:41,334: ERROR/MainProcess] consumer: Cannot connect to amqp://myuser:**@127.0.0.1:5672//: [Errno 111] Connection refused.
Trying again in 18.00 seconds... (9/100)

[2022-06-27 04:06:59,369: ERROR/MainProcess] consumer: Cannot connect to amqp://myuser:**@127.0.0.1:5672//: [Errno 111] Connection refused.
Trying again in 20.00 seconds... (10/100)

[2022-06-27 04:07:19,443: ERROR/MainProcess] consumer: Cannot connect to amqp://myuser:**@127.0.0.1:5672//: [Errno 111] Connection refused.
Trying again in 22.00 seconds... (11/100)

[2022-06-27 04:07:41,501: ERROR/MainProcess] consumer: Cannot connect to amqp://myuser:**@127.0.0.1:5672//: [Errno 111] Connection refused.
Trying again in 24.00 seconds... (12/100)

[2022-06-27 04:08:05,543: ERROR/MainProcess] consumer: Cannot connect to amqp://myuser:**@127.0.0.1:5672//: [Errno 111] Connection refused.
Trying again in 26.00 seconds... (13/100)

[2022-06-27 04:08:31,613: ERROR/MainProcess] consumer: Cannot connect to amqp://myuser:**@127.0.0.1:5672//: [Errno 111] Connection refused.
Trying again in 28.00 seconds... (14/100)

[2022-06-27 04:08:59,679: ERROR/MainProcess] consumer: Cannot connect to amqp://myuser:**@127.0.0.1:5672//: [Errno 111] Connection refused.
Trying again in 30.00 seconds... (15/100)

[2022-06-27 04:09:29,764: ERROR/MainProcess] consumer: Cannot connect to amqp://myuser:**@127.0.0.1:5672//: [Errno 111] Connection refused.
Trying again in 32.00 seconds... (16/100)

[2022-06-27 04:10:01,847: ERROR/MainProcess] consumer: Cannot connect to amqp://myuser:**@127.0.0.1:5672//: [Errno 111] Connection refused.
Trying again in 32.00 seconds... (16/100)

[2022-06-27 04:10:33,912: ERROR/MainProcess] consumer: Cannot connect to amqp://myuser:**@127.0.0.1:5672//: [Errno 111] Connection refused.
Trying again in 32.00 seconds... (16/100)

[2022-06-27 04:11:06,001: ERROR/MainProcess] consumer: Cannot connect to amqp://myuser:**@127.0.0.1:5672//: [Errno 111] Connection refused.
Trying again in 32.00 seconds... (16/100)

[2022-06-27 04:11:30,718: ERROR/MainProcess] consumer: Cannot connect to amqp://myuser:**@127.0.0.1:5672//: [Errno 111] Connection refused.
Trying again in 2.00 seconds... (1/100)

[2022-06-27 04:11:32,730: ERROR/MainProcess] consumer: Cannot connect to amqp://myuser:**@127.0.0.1:5672//: [Errno 111] Connection refused.
Trying again in 4.00 seconds... (2/100)

[2022-06-27 04:11:36,749: ERROR/MainProcess] consumer: Cannot connect to amqp://myuser:**@127.0.0.1:5672//: [Errno 111] Connection refused.
Trying again in 6.00 seconds... (3/100)

[2022-06-27 04:11:42,774: ERROR/MainProcess] consumer: Cannot connect to amqp://myuser:**@127.0.0.1:5672//: [Errno 111] Connection refused.
Trying again in 8.00 seconds... (4/100)

[2022-06-27 04:11:50,809: ERROR/MainProcess] consumer: Cannot connect to amqp://myuser:**@127.0.0.1:5672//: [Errno 111] Connection refused.
Trying again in 10.00 seconds... (5/100)

[2022-06-27 04:12:00,828: ERROR/MainProcess] consumer: Cannot connect to amqp://myuser:**@127.0.0.1:5672//: [Errno 111] Connection refused.
Trying again in 12.00 seconds... (6/100)

[2022-06-27 04:12:12,874: ERROR/MainProcess] consumer: Cannot connect to amqp://myuser:**@127.0.0.1:5672//: [Errno 111] Connection refused.
Trying again in 14.00 seconds... (7/100)

[2022-06-27 04:12:26,925: ERROR/MainProcess] consumer: Cannot connect to amqp://myuser:**@127.0.0.1:5672//: [Errno 111] Connection refused.
Trying again in 16.00 seconds... (8/100)

[2022-06-27 04:12:42,965: ERROR/MainProcess] consumer: Cannot connect to amqp://myuser:**@127.0.0.1:5672//: [Errno 111] Connection refused.
Trying again in 18.00 seconds... (9/100)

[2022-06-27 04:13:00,990: ERROR/MainProcess] consumer: Cannot connect to amqp://myuser:**@127.0.0.1:5672//: [Errno 111] Connection refused.
Trying again in 20.00 seconds... (10/100)

[2022-06-27 04:13:21,050: ERROR/MainProcess] consumer: Cannot connect to amqp://myuser:**@127.0.0.1:5672//: [Errno 111] Connection refused.
Trying again in 22.00 seconds... (11/100)

[2022-06-27 04:13:43,098: ERROR/MainProcess] consumer: Cannot connect to amqp://myuser:**@127.0.0.1:5672//: [Errno 111] Connection refused.
Trying again in 24.00 seconds... (12/100)

[2022-06-27 04:14:07,157: ERROR/MainProcess] consumer: Cannot connect to amqp://myuser:**@127.0.0.1:5672//: [Errno 111] Connection refused.
Trying again in 26.00 seconds... (13/100)

[2022-06-27 04:14:33,228: ERROR/MainProcess] consumer: Cannot connect to amqp://myuser:**@127.0.0.1:5672//: [Errno 111] Connection refused.
Trying again in 28.00 seconds... (14/100)

[2022-06-27 04:15:01,915: ERROR/MainProcess] consumer: Cannot connect to amqp://myuser:**@127.0.0.1:5672//: [Errno 111] Connection refused.
Trying again in 30.00 seconds... (15/100)

[2022-06-27 04:15:31,975: ERROR/MainProcess] consumer: Cannot connect to amqp://myuser:**@127.0.0.1:5672//: [Errno 111] Connection refused.
Trying again in 32.00 seconds... (16/100)

[2022-06-27 04:16:04,043: ERROR/MainProcess] consumer: Cannot connect to amqp://myuser:**@127.0.0.1:5672//: [Errno 111] Connection refused.
Trying again in 32.00 seconds... (16/100)

[2022-06-27 04:16:36,110: ERROR/MainProcess] consumer: Cannot connect to amqp://myuser:**@127.0.0.1:5672//: [Errno 111] Connection refused.
Trying again in 32.00 seconds... (16/100)

[2022-06-27 04:17:08,184: ERROR/MainProcess] consumer: Cannot connect to amqp://myuser:**@127.0.0.1:5672//: [Errno 111] Connection refused.
Trying again in 32.00 seconds... (16/100)

[2022-06-27 04:17:40,257: ERROR/MainProcess] consumer: Cannot connect to amqp://myuser:**@127.0.0.1:5672//: [Errno 111] Connection refused.
Trying again in 32.00 seconds... (16/100)

[2022-06-27 04:18:12,297: ERROR/MainProcess] consumer: Cannot connect to amqp://myuser:**@127.0.0.1:5672//: [Errno 111] Connection refused.
Trying again in 32.00 seconds... (16/100)

[2022-06-27 04:18:44,364: ERROR/MainProcess] consumer: Cannot connect to amqp://myuser:**@127.0.0.1:5672//: [Errno 111] Connection refused.
Trying again in 32.00 seconds... (16/100)

[2022-06-27 04:18:45,594: CRITICAL/MainProcess] Unrecoverable error: OperationalError('[Errno 32] Broken pipe')
Traceback (most recent call last):
  File "/usr/local/lib/python3.9/site-packages/amqp/transport.py", line 137, in _connect
    entries = socket.getaddrinfo(
  File "/usr/local/lib/python3.9/socket.py", line 953, in getaddrinfo
    for res in _socket.getaddrinfo(host, port, family, type, proto, flags):
socket.gaierror: [Errno -9] Address family for hostname not supported

During handling of the above exception, another exception occurred:

Traceback (most recent call last):
  File "/usr/local/lib/python3.9/site-packages/kombu/utils/functional.py", line 344, in retry_over_time
    return fun(*args, **kwargs)
  File "/usr/local/lib/python3.9/site-packages/kombu/connection.py", line 874, in _connection_factory
    self._connection = self._establish_connection()
  File "/usr/local/lib/python3.9/site-packages/kombu/connection.py", line 809, in _establish_connection
    conn = self.transport.establish_connection()
  File "/usr/local/lib/python3.9/site-packages/kombu/transport/pyamqp.py", line 130, in establish_connection
    conn.connect()
  File "/usr/local/lib/python3.9/site-packages/amqp/connection.py", line 314, in connect
    self.transport.connect()
  File "/usr/local/lib/python3.9/site-packages/amqp/transport.py", line 78, in connect
    self._connect(self.host, self.port, self.connect_timeout)
  File "/usr/local/lib/python3.9/site-packages/amqp/transport.py", line 146, in _connect
    raise (e
  File "/usr/local/lib/python3.9/site-packages/amqp/transport.py", line 162, in _connect
    self.sock.connect(sa)
ConnectionRefusedError: [Errno 111] Connection refused

During handling of the above exception, another exception occurred:

Traceback (most recent call last):
  File "/usr/local/lib/python3.9/site-packages/kombu/connection.py", line 454, in _reraise_as_library_errors
    yield
  File "/usr/local/lib/python3.9/site-packages/kombu/connection.py", line 441, in _ensure_connection
    return retry_over_time(
  File "/usr/local/lib/python3.9/site-packages/kombu/utils/functional.py", line 358, in retry_over_time
    sleep(1.0)
  File "/usr/local/lib/python3.9/site-packages/celery/apps/worker.py", line 276, in _handle_request
    safe_say('worker: {0} shutdown (MainProcess)'.format(how))
  File "/usr/local/lib/python3.9/site-packages/celery/apps/worker.py", line 86, in safe_say
    print('\n{0}'.format(msg), file=sys.__stderr__)
BrokenPipeError: [Errno 32] Broken pipe

During handling of the above exception, another exception occurred:

Traceback (most recent call last):
  File "/usr/local/lib/python3.9/site-packages/celery/worker/worker.py", line 208, in start
    self.blueprint.start(self)
  File "/usr/local/lib/python3.9/site-packages/celery/bootsteps.py", line 119, in start
    step.start(parent)
  File "/usr/local/lib/python3.9/site-packages/celery/bootsteps.py", line 369, in start
    return self.obj.start()
  File "/usr/local/lib/python3.9/site-packages/celery/worker/consumer/consumer.py", line 318, in start
    blueprint.start(self)
  File "/usr/local/lib/python3.9/site-packages/celery/bootsteps.py", line 119, in start
    step.start(parent)
  File "/usr/local/lib/python3.9/site-packages/celery/worker/consumer/connection.py", line 23, in start
    c.connection = c.connect()
  File "/usr/local/lib/python3.9/site-packages/celery/worker/consumer/consumer.py", line 405, in connect
    conn = self.connection_for_read(heartbeat=self.amqheartbeat)
  File "/usr/local/lib/python3.9/site-packages/celery/worker/consumer/consumer.py", line 411, in connection_for_read
    return self.ensure_connected(
  File "/usr/local/lib/python3.9/site-packages/celery/worker/consumer/consumer.py", line 437, in ensure_connected
    conn = conn.ensure_connection(
  File "/usr/local/lib/python3.9/site-packages/kombu/connection.py", line 389, in ensure_connection
    self._ensure_connection(*args, **kwargs)
  File "/usr/local/lib/python3.9/site-packages/kombu/connection.py", line 441, in _ensure_connection
    return retry_over_time(
  File "/usr/local/lib/python3.9/contextlib.py", line 135, in __exit__
    self.gen.throw(type, value, traceback)
  File "/usr/local/lib/python3.9/site-packages/kombu/connection.py", line 458, in _reraise_as_library_errors
    reraise(ConnectionError, ConnectionError(text_t(exc)),
  File "/usr/local/lib/python3.9/site-packages/vine/five.py", line 194, in reraise
    raise value.with_traceback(tb)
  File "/usr/local/lib/python3.9/site-packages/kombu/connection.py", line 454, in _reraise_as_library_errors
    yield
  File "/usr/local/lib/python3.9/site-packages/kombu/connection.py", line 441, in _ensure_connection
    return retry_over_time(
  File "/usr/local/lib/python3.9/site-packages/kombu/utils/functional.py", line 358, in retry_over_time
    sleep(1.0)
  File "/usr/local/lib/python3.9/site-packages/celery/apps/worker.py", line 276, in _handle_request
    safe_say('worker: {0} shutdown (MainProcess)'.format(how))
  File "/usr/local/lib/python3.9/site-packages/celery/apps/worker.py", line 86, in safe_say
    print('\n{0}'.format(msg), file=sys.__stderr__)
kombu.exceptions.OperationalError: [Errno 32] Broken pipe
[2022-06-27 04:20:51,001: ERROR/MainProcess] consumer: Cannot connect to amqp://myuser:**@127.0.0.1:5672//: [Errno 111] Connection refused.
Trying again in 2.00 seconds... (1/100)

[2022-06-27 04:20:53,011: ERROR/MainProcess] consumer: Cannot connect to amqp://myuser:**@127.0.0.1:5672//: [Errno 111] Connection refused.
Trying again in 4.00 seconds... (2/100)

[2022-06-27 04:20:57,001: ERROR/MainProcess] consumer: Cannot connect to amqp://myuser:**@127.0.0.1:5672//: [Errno 111] Connection refused.
Trying again in 6.00 seconds... (3/100)

[2022-06-27 04:21:03,023: ERROR/MainProcess] consumer: Cannot connect to amqp://myuser:**@127.0.0.1:5672//: [Errno 111] Connection refused.
Trying again in 8.00 seconds... (4/100)

[2022-06-27 04:21:11,054: ERROR/MainProcess] consumer: Cannot connect to amqp://myuser:**@127.0.0.1:5672//: [Errno 111] Connection refused.
Trying again in 10.00 seconds... (5/100)

[2022-06-27 04:21:21,082: ERROR/MainProcess] consumer: Cannot connect to amqp://myuser:**@127.0.0.1:5672//: [Errno 111] Connection refused.
Trying again in 12.00 seconds... (6/100)

[2022-06-27 04:21:33,089: ERROR/MainProcess] consumer: Cannot connect to amqp://myuser:**@127.0.0.1:5672//: [Errno 111] Connection refused.
Trying again in 14.00 seconds... (7/100)

[2022-06-27 04:21:47,121: ERROR/MainProcess] consumer: Cannot connect to amqp://myuser:**@127.0.0.1:5672//: [Errno 111] Connection refused.
Trying again in 16.00 seconds... (8/100)

[2022-06-27 04:22:03,121: ERROR/MainProcess] consumer: Cannot connect to amqp://myuser:**@127.0.0.1:5672//: [Errno 111] Connection refused.
Trying again in 18.00 seconds... (9/100)

[2022-06-27 04:22:21,171: ERROR/MainProcess] consumer: Cannot connect to amqp://myuser:**@127.0.0.1:5672//: [Errno 111] Connection refused.
Trying again in 20.00 seconds... (10/100)

[2022-06-27 04:22:26,614: ERROR/MainProcess] consumer: Cannot connect to amqp://myuser:**@127.0.0.1:5672//: [Errno 111] Connection refused.
Trying again in 2.00 seconds... (1/100)

[2022-06-27 04:22:28,628: ERROR/MainProcess] consumer: Cannot connect to amqp://myuser:**@127.0.0.1:5672//: [Errno 111] Connection refused.
Trying again in 4.00 seconds... (2/100)

[2022-06-27 04:22:32,645: ERROR/MainProcess] consumer: Cannot connect to amqp://myuser:**@127.0.0.1:5672//: [Errno 111] Connection refused.
Trying again in 6.00 seconds... (3/100)

[2022-06-27 04:22:38,666: ERROR/MainProcess] consumer: Cannot connect to amqp://myuser:**@127.0.0.1:5672//: [Errno 111] Connection refused.
Trying again in 8.00 seconds... (4/100)

[2022-06-27 04:22:46,694: ERROR/MainProcess] consumer: Cannot connect to amqp://myuser:**@127.0.0.1:5672//: [Errno 111] Connection refused.
Trying again in 10.00 seconds... (5/100)

[2022-06-27 04:22:56,694: ERROR/MainProcess] consumer: Cannot connect to amqp://myuser:**@127.0.0.1:5672//: [Errno 111] Connection refused.
Trying again in 12.00 seconds... (6/100)

[2022-06-27 04:23:08,722: ERROR/MainProcess] consumer: Cannot connect to amqp://myuser:**@127.0.0.1:5672//: [Errno 111] Connection refused.
Trying again in 14.00 seconds... (7/100)

[2022-06-27 04:23:22,760: ERROR/MainProcess] consumer: Cannot connect to amqp://myuser:**@127.0.0.1:5672//: [Errno 111] Connection refused.
Trying again in 16.00 seconds... (8/100)

[2022-06-27 04:23:38,779: ERROR/MainProcess] consumer: Cannot connect to amqp://myuser:**@127.0.0.1:5672//: [Errno 111] Connection refused.
Trying again in 18.00 seconds... (9/100)

[2022-06-27 04:23:56,805: ERROR/MainProcess] consumer: Cannot connect to amqp://myuser:**@127.0.0.1:5672//: [Errno 111] Connection refused.
Trying again in 20.00 seconds... (10/100)

[2022-06-27 04:24:16,869: ERROR/MainProcess] consumer: Cannot connect to amqp://myuser:**@127.0.0.1:5672//: [Errno 111] Connection refused.
Trying again in 22.00 seconds... (11/100)

[2022-06-27 04:24:38,902: ERROR/MainProcess] consumer: Cannot connect to amqp://myuser:**@127.0.0.1:5672//: [Errno 111] Connection refused.
Trying again in 24.00 seconds... (12/100)

[2022-06-27 04:25:02,939: ERROR/MainProcess] consumer: Cannot connect to amqp://myuser:**@127.0.0.1:5672//: [Errno 111] Connection refused.
Trying again in 26.00 seconds... (13/100)

[2022-06-27 04:25:28,975: ERROR/MainProcess] consumer: Cannot connect to amqp://myuser:**@127.0.0.1:5672//: [Errno 111] Connection refused.
Trying again in 28.00 seconds... (14/100)

[2022-06-27 04:25:57,023: ERROR/MainProcess] consumer: Cannot connect to amqp://myuser:**@127.0.0.1:5672//: [Errno 111] Connection refused.
Trying again in 30.00 seconds... (15/100)

[2022-06-27 04:26:27,078: ERROR/MainProcess] consumer: Cannot connect to amqp://myuser:**@127.0.0.1:5672//: [Errno 111] Connection refused.
Trying again in 32.00 seconds... (16/100)

[2022-06-27 04:26:59,121: ERROR/MainProcess] consumer: Cannot connect to amqp://myuser:**@127.0.0.1:5672//: [Errno 111] Connection refused.
Trying again in 32.00 seconds... (16/100)

[2022-06-27 04:27:31,174: ERROR/MainProcess] consumer: Cannot connect to amqp://myuser:**@127.0.0.1:5672//: [Errno 111] Connection refused.
Trying again in 32.00 seconds... (16/100)

[2022-06-27 04:28:03,237: ERROR/MainProcess] consumer: Cannot connect to amqp://myuser:**@127.0.0.1:5672//: [Errno 111] Connection refused.
Trying again in 32.00 seconds... (16/100)

[2022-06-27 04:28:35,305: ERROR/MainProcess] consumer: Cannot connect to amqp://myuser:**@127.0.0.1:5672//: [Errno 111] Connection refused.
Trying again in 32.00 seconds... (16/100)

[2022-06-27 04:29:07,380: ERROR/MainProcess] consumer: Cannot connect to amqp://myuser:**@127.0.0.1:5672//: [Errno 111] Connection refused.
Trying again in 32.00 seconds... (16/100)

[2022-06-27 04:29:39,445: ERROR/MainProcess] consumer: Cannot connect to amqp://myuser:**@127.0.0.1:5672//: [Errno 111] Connection refused.
Trying again in 32.00 seconds... (16/100)

[2022-06-27 04:30:11,505: ERROR/MainProcess] consumer: Cannot connect to amqp://myuser:**@127.0.0.1:5672//: [Errno 111] Connection refused.
Trying again in 32.00 seconds... (16/100)

[2022-06-27 04:30:43,570: ERROR/MainProcess] consumer: Cannot connect to amqp://myuser:**@127.0.0.1:5672//: [Errno 111] Connection refused.
Trying again in 32.00 seconds... (16/100)

[2022-06-27 04:31:15,640: ERROR/MainProcess] consumer: Cannot connect to amqp://myuser:**@127.0.0.1:5672//: [Errno 111] Connection refused.
Trying again in 32.00 seconds... (16/100)

[2022-06-27 04:31:47,707: ERROR/MainProcess] consumer: Cannot connect to amqp://myuser:**@127.0.0.1:5672//: [Errno 111] Connection refused.
Trying again in 32.00 seconds... (16/100)

[2022-06-27 04:32:19,785: ERROR/MainProcess] consumer: Cannot connect to amqp://myuser:**@127.0.0.1:5672//: [Errno 111] Connection refused.
Trying again in 32.00 seconds... (16/100)

[2022-06-27 04:32:51,862: ERROR/MainProcess] consumer: Cannot connect to amqp://myuser:**@127.0.0.1:5672//: [Errno 111] Connection refused.
Trying again in 32.00 seconds... (16/100)

[2022-06-27 04:33:23,935: ERROR/MainProcess] consumer: Cannot connect to amqp://myuser:**@127.0.0.1:5672//: [Errno 111] Connection refused.
Trying again in 32.00 seconds... (16/100)

[2022-06-27 06:07:21,801: ERROR/MainProcess] consumer: Cannot connect to amqp://guest:**@127.0.0.1:5672//: [Errno 111] Connection refused.
Trying again in 2.00 seconds... (1/100)

[2022-06-27 06:07:23,810: ERROR/MainProcess] consumer: Cannot connect to amqp://guest:**@127.0.0.1:5672//: [Errno 111] Connection refused.
Trying again in 4.00 seconds... (2/100)

[2022-06-27 06:07:27,826: ERROR/MainProcess] consumer: Cannot connect to amqp://guest:**@127.0.0.1:5672//: [Errno 111] Connection refused.
Trying again in 6.00 seconds... (3/100)

[2022-06-27 06:07:33,823: ERROR/MainProcess] consumer: Cannot connect to amqp://guest:**@127.0.0.1:5672//: [Errno 111] Connection refused.
Trying again in 8.00 seconds... (4/100)

[2022-06-27 06:07:41,849: ERROR/MainProcess] consumer: Cannot connect to amqp://guest:**@127.0.0.1:5672//: [Errno 111] Connection refused.
Trying again in 10.00 seconds... (5/100)

[2022-06-27 06:07:51,883: ERROR/MainProcess] consumer: Cannot connect to amqp://guest:**@127.0.0.1:5672//: [Errno 111] Connection refused.
Trying again in 12.00 seconds... (6/100)

[2022-06-27 06:08:03,894: ERROR/MainProcess] consumer: Cannot connect to amqp://guest:**@127.0.0.1:5672//: [Errno 111] Connection refused.
Trying again in 14.00 seconds... (7/100)

[2022-06-27 06:08:17,925: ERROR/MainProcess] consumer: Cannot connect to amqp://guest:**@127.0.0.1:5672//: [Errno 111] Connection refused.
Trying again in 16.00 seconds... (8/100)

[2022-06-27 06:08:33,948: ERROR/MainProcess] consumer: Cannot connect to amqp://guest:**@127.0.0.1:5672//: [Errno 111] Connection refused.
Trying again in 18.00 seconds... (9/100)

[2022-06-27 06:08:51,991: ERROR/MainProcess] consumer: Cannot connect to amqp://guest:**@127.0.0.1:5672//: [Errno 111] Connection refused.
Trying again in 20.00 seconds... (10/100)

[2022-06-27 06:09:12,018: ERROR/MainProcess] consumer: Cannot connect to amqp://guest:**@127.0.0.1:5672//: [Errno 111] Connection refused.
Trying again in 22.00 seconds... (11/100)

[2022-06-27 06:09:34,053: ERROR/MainProcess] consumer: Cannot connect to amqp://guest:**@127.0.0.1:5672//: [Errno 111] Connection refused.
Trying again in 24.00 seconds... (12/100)

[2022-06-27 06:09:58,103: ERROR/MainProcess] consumer: Cannot connect to amqp://guest:**@127.0.0.1:5672//: [Errno 111] Connection refused.
Trying again in 26.00 seconds... (13/100)

[2022-06-27 06:10:24,142: ERROR/MainProcess] consumer: Cannot connect to amqp://guest:**@127.0.0.1:5672//: [Errno 111] Connection refused.
Trying again in 28.00 seconds... (14/100)

[2022-06-27 06:10:52,180: ERROR/MainProcess] consumer: Cannot connect to amqp://guest:**@127.0.0.1:5672//: [Errno 111] Connection refused.
Trying again in 30.00 seconds... (15/100)

[2022-06-27 06:11:22,223: ERROR/MainProcess] consumer: Cannot connect to amqp://guest:**@127.0.0.1:5672//: [Errno 111] Connection refused.
Trying again in 32.00 seconds... (16/100)

[2022-06-27 06:11:54,278: ERROR/MainProcess] consumer: Cannot connect to amqp://guest:**@127.0.0.1:5672//: [Errno 111] Connection refused.
Trying again in 32.00 seconds... (16/100)

[2022-06-27 06:12:26,315: ERROR/MainProcess] consumer: Cannot connect to amqp://guest:**@127.0.0.1:5672//: [Errno 111] Connection refused.
Trying again in 32.00 seconds... (16/100)

[2022-06-27 06:12:31,350: ERROR/MainProcess] consumer: Cannot connect to amqp://guest:**@rabbit:5672//: failed to resolve broker hostname.
Trying again in 2.00 seconds... (1/100)

[2022-06-27 06:12:33,373: ERROR/MainProcess] consumer: Cannot connect to amqp://guest:**@rabbit:5672//: failed to resolve broker hostname.
Trying again in 4.00 seconds... (2/100)

[2022-06-27 06:12:37,399: ERROR/MainProcess] consumer: Cannot connect to amqp://guest:**@rabbit:5672//: failed to resolve broker hostname.
Trying again in 6.00 seconds... (3/100)

[2022-06-27 06:12:43,442: ERROR/MainProcess] consumer: Cannot connect to amqp://guest:**@rabbit:5672//: failed to resolve broker hostname.
Trying again in 8.00 seconds... (4/100)

[2022-06-27 06:12:51,485: ERROR/MainProcess] consumer: Cannot connect to amqp://guest:**@rabbit:5672//: failed to resolve broker hostname.
Trying again in 10.00 seconds... (5/100)

[2022-06-27 06:13:01,506: ERROR/MainProcess] consumer: Cannot connect to amqp://guest:**@rabbit:5672//: failed to resolve broker hostname.
Trying again in 12.00 seconds... (6/100)

[2022-06-27 06:13:13,553: ERROR/MainProcess] consumer: Cannot connect to amqp://guest:**@rabbit:5672//: failed to resolve broker hostname.
Trying again in 14.00 seconds... (7/100)

[2022-06-27 06:13:27,601: ERROR/MainProcess] consumer: Cannot connect to amqp://guest:**@rabbit:5672//: failed to resolve broker hostname.
Trying again in 16.00 seconds... (8/100)

[2022-06-27 06:13:43,641: ERROR/MainProcess] consumer: Cannot connect to amqp://guest:**@rabbit:5672//: failed to resolve broker hostname.
Trying again in 18.00 seconds... (9/100)

[2022-06-27 06:14:01,679: ERROR/MainProcess] consumer: Cannot connect to amqp://guest:**@rabbit:5672//: failed to resolve broker hostname.
Trying again in 20.00 seconds... (10/100)

[2022-06-27 06:14:21,739: ERROR/MainProcess] consumer: Cannot connect to amqp://guest:**@rabbit:5672//: failed to resolve broker hostname.
Trying again in 22.00 seconds... (11/100)

[2022-06-27 06:14:43,789: ERROR/MainProcess] consumer: Cannot connect to amqp://guest:**@rabbit:5672//: failed to resolve broker hostname.
Trying again in 24.00 seconds... (12/100)

[2022-06-27 06:15:07,848: ERROR/MainProcess] consumer: Cannot connect to amqp://guest:**@rabbit:5672//: failed to resolve broker hostname.
Trying again in 26.00 seconds... (13/100)

[2022-06-27 06:15:33,900: ERROR/MainProcess] consumer: Cannot connect to amqp://guest:**@rabbit:5672//: failed to resolve broker hostname.
Trying again in 28.00 seconds... (14/100)

[2022-06-27 06:16:01,953: ERROR/MainProcess] consumer: Cannot connect to amqp://guest:**@rabbit:5672//: failed to resolve broker hostname.
Trying again in 30.00 seconds... (15/100)

[2022-06-27 06:16:32,007: ERROR/MainProcess] consumer: Cannot connect to amqp://guest:**@rabbit:5672//: failed to resolve broker hostname.
Trying again in 32.00 seconds... (16/100)

[2022-06-27 06:17:04,063: ERROR/MainProcess] consumer: Cannot connect to amqp://guest:**@rabbit:5672//: failed to resolve broker hostname.
Trying again in 32.00 seconds... (16/100)

[2022-06-27 06:17:36,117: ERROR/MainProcess] consumer: Cannot connect to amqp://guest:**@rabbit:5672//: failed to resolve broker hostname.
Trying again in 32.00 seconds... (16/100)

[2022-06-27 06:18:08,177: ERROR/MainProcess] consumer: Cannot connect to amqp://guest:**@rabbit:5672//: failed to resolve broker hostname.
Trying again in 32.00 seconds... (16/100)

[2022-06-27 06:18:40,245: ERROR/MainProcess] consumer: Cannot connect to amqp://guest:**@rabbit:5672//: failed to resolve broker hostname.
Trying again in 32.00 seconds... (16/100)

[2022-06-27 06:19:12,326: ERROR/MainProcess] consumer: Cannot connect to amqp://guest:**@rabbit:5672//: failed to resolve broker hostname.
Trying again in 32.00 seconds... (16/100)

[2022-06-27 06:19:44,419: ERROR/MainProcess] consumer: Cannot connect to amqp://guest:**@rabbit:5672//: failed to resolve broker hostname.
Trying again in 32.00 seconds... (16/100)

[2022-06-27 06:20:16,506: ERROR/MainProcess] consumer: Cannot connect to amqp://guest:**@rabbit:5672//: failed to resolve broker hostname.
Trying again in 32.00 seconds... (16/100)

[2022-06-27 06:20:48,562: ERROR/MainProcess] consumer: Cannot connect to amqp://guest:**@rabbit:5672//: failed to resolve broker hostname.
Trying again in 32.00 seconds... (16/100)

[2022-06-27 06:21:20,628: ERROR/MainProcess] consumer: Cannot connect to amqp://guest:**@rabbit:5672//: failed to resolve broker hostname.
Trying again in 32.00 seconds... (16/100)

[2022-06-27 06:21:52,685: ERROR/MainProcess] consumer: Cannot connect to amqp://guest:**@rabbit:5672//: failed to resolve broker hostname.
Trying again in 32.00 seconds... (16/100)

[2022-06-27 06:22:24,732: ERROR/MainProcess] consumer: Cannot connect to amqp://guest:**@rabbit:5672//: failed to resolve broker hostname.
Trying again in 32.00 seconds... (16/100)

[2022-06-27 06:22:56,782: ERROR/MainProcess] consumer: Cannot connect to amqp://guest:**@rabbit:5672//: failed to resolve broker hostname.
Trying again in 32.00 seconds... (16/100)

[2022-06-27 06:23:28,821: ERROR/MainProcess] consumer: Cannot connect to amqp://guest:**@rabbit:5672//: failed to resolve broker hostname.
Trying again in 32.00 seconds... (16/100)

[2022-06-27 06:24:00,887: ERROR/MainProcess] consumer: Cannot connect to amqp://guest:**@rabbit:5672//: failed to resolve broker hostname.
Trying again in 32.00 seconds... (16/100)

[2022-06-27 06:24:32,958: ERROR/MainProcess] consumer: Cannot connect to amqp://guest:**@rabbit:5672//: failed to resolve broker hostname.
Trying again in 32.00 seconds... (16/100)

[2022-06-27 06:25:05,020: ERROR/MainProcess] consumer: Cannot connect to amqp://guest:**@rabbit:5672//: failed to resolve broker hostname.
Trying again in 32.00 seconds... (16/100)

[2022-06-27 06:25:36,675: INFO/MainProcess] Connected to amqp://guest:**@rabbitmq:5672//
[2022-06-27 06:25:36,691: INFO/MainProcess] mingle: searching for neighbors
[2022-06-27 06:25:37,717: INFO/MainProcess] mingle: all alone
[2022-06-27 06:25:37,741: INFO/MainProcess] celery@cdabeaaed288 ready.
[2022-06-27 06:25:52,238: INFO/MainProcess] Events of group {task} enabled by remote.
[2022-06-27 06:26:00,908: INFO/MainProcess] Received task: create_task[a652cdba-f841-46d9-b564-1f87db8b078b]  
[2022-06-27 06:26:30,939: INFO/ForkPoolWorker-3] Task create_task[a652cdba-f841-46d9-b564-1f87db8b078b] succeeded in 30.048684401999935s: True
[2022-06-27 06:29:56,299: INFO/MainProcess] Received task: create_task[957c6d76-6673-41da-9577-675be4f180df]  
[2022-06-27 06:30:06,296: INFO/ForkPoolWorker-3] Task create_task[957c6d76-6673-41da-9577-675be4f180df] succeeded in 10.013416774000007s: True
[2022-06-27 06:36:11,096: INFO/MainProcess] Connected to amqp://guest:**@rabbitmq:5672//
[2022-06-27 06:36:11,111: INFO/MainProcess] mingle: searching for neighbors
[2022-06-27 06:36:12,145: INFO/MainProcess] mingle: all alone
[2022-06-27 06:36:12,168: INFO/MainProcess] celery@1f4ec7a2883f ready.
[2022-06-27 06:36:16,360: INFO/MainProcess] Events of group {task} enabled by remote.
[2022-06-27 06:36:21,680: INFO/MainProcess] Received task: create_task[4161720b-aba3-4047-a72b-a43b456cc090]  
[2022-06-27 06:36:31,687: INFO/ForkPoolWorker-3] Task create_task[4161720b-aba3-4047-a72b-a43b456cc090] succeeded in 10.024969557999839s: True
[2022-06-27 06:38:01,370: INFO/MainProcess] Connected to amqp://guest:**@rabbitmq:5672//
[2022-06-27 06:38:01,384: INFO/MainProcess] mingle: searching for neighbors
[2022-06-27 06:38:02,414: INFO/MainProcess] mingle: all alone
[2022-06-27 06:38:02,435: INFO/MainProcess] celery@2a69f12cb7be ready.
[2022-06-27 06:38:06,626: INFO/MainProcess] Events of group {task} enabled by remote.
[2022-06-27 06:38:13,094: INFO/MainProcess] Received task: create_task[0ed19b0b-c724-481d-a2c0-c62ee8c296ee]  
[2022-06-27 06:38:23,124: INFO/ForkPoolWorker-3] Task create_task[0ed19b0b-c724-481d-a2c0-c62ee8c296ee] succeeded in 10.027138243000081s: True
[2022-06-27 06:39:56,555: INFO/MainProcess] Connected to amqp://guest:**@rabbitmq:5672//
[2022-06-27 06:39:56,566: INFO/MainProcess] mingle: searching for neighbors
[2022-06-27 06:39:57,594: INFO/MainProcess] mingle: all alone
[2022-06-27 06:39:57,596: INFO/MainProcess] celery@612df19221e9 ready.
[2022-06-27 06:40:01,798: INFO/MainProcess] Events of group {task} enabled by remote.
[2022-06-27 06:41:03,776: INFO/MainProcess] Received task: create_task[3961015e-bbbf-43ea-8a4e-84b772ded4f6]  
[2022-06-27 06:41:13,807: INFO/ForkPoolWorker-3] Task create_task[3961015e-bbbf-43ea-8a4e-84b772ded4f6] succeeded in 10.028180970000449s: True
[2022-06-27 06:57:05,351: INFO/MainProcess] Received task: create_task[ab9c842c-9327-4283-92cc-402b966a4a6c]  
[2022-06-27 06:58:45,317: INFO/ForkPoolWorker-3] Task create_task[ab9c842c-9327-4283-92cc-402b966a4a6c] succeeded in 100.01873752899974s: True
[2022-06-27 07:07:47,801: INFO/MainProcess] Connected to amqp://guest:**@rabbitmq:5672//
[2022-06-27 07:07:47,812: INFO/MainProcess] mingle: searching for neighbors
[2022-06-27 07:07:48,840: INFO/MainProcess] mingle: all alone
[2022-06-27 07:07:48,865: INFO/MainProcess] celery@0d482fc9c354 ready.
[2022-06-27 07:07:53,072: INFO/MainProcess] Events of group {task} enabled by remote.
[2022-06-27 07:08:11,497: INFO/MainProcess] Received task: create_task[3247dc36-01a2-4d7e-897f-49f6f0ebb88d]  
[2022-06-27 07:09:51,551: INFO/ForkPoolWorker-3] Task create_task[3247dc36-01a2-4d7e-897f-49f6f0ebb88d] succeeded in 100.11177348199999s: True
[2022-06-27 07:21:28,090: INFO/MainProcess] Connected to amqp://guest:**@rabbitmq:5672//
[2022-06-27 07:21:28,102: INFO/MainProcess] mingle: searching for neighbors
[2022-06-27 07:21:29,131: INFO/MainProcess] mingle: all alone
[2022-06-27 07:21:29,156: INFO/MainProcess] celery@a6b9e5b5cb45 ready.
[2022-06-27 07:21:33,319: INFO/MainProcess] Events of group {task} enabled by remote.
[2022-06-27 07:21:35,443: INFO/MainProcess] Received task: create_task[af2cbe44-135a-4a9b-8ebd-1cba3d402ffe]  
[2022-06-27 07:23:15,488: INFO/ForkPoolWorker-3] Task create_task[af2cbe44-135a-4a9b-8ebd-1cba3d402ffe] succeeded in 100.1050888310001s: True
[2022-06-27 07:40:10,799: ERROR/MainProcess] consumer: Cannot connect to amqp://guest:**@rabbitmq:5672//: [Errno 111] Connection refused.
Trying again in 2.00 seconds... (1/100)

[2022-06-27 07:40:12,807: ERROR/MainProcess] consumer: Cannot connect to amqp://guest:**@rabbitmq:5672//: [Errno 111] Connection refused.
Trying again in 4.00 seconds... (2/100)

[2022-06-27 07:40:16,819: ERROR/MainProcess] consumer: Cannot connect to amqp://guest:**@rabbitmq:5672//: [Errno 111] Connection refused.
Trying again in 6.00 seconds... (3/100)

[2022-06-27 07:40:22,824: INFO/MainProcess] Connected to amqp://guest:**@rabbitmq:5672//
[2022-06-27 07:40:22,839: INFO/MainProcess] mingle: searching for neighbors
[2022-06-27 07:40:23,868: INFO/MainProcess] mingle: all alone
[2022-06-27 07:40:23,893: INFO/MainProcess] celery@eab570c86ed9 ready.
[2022-06-27 07:40:25,906: INFO/MainProcess] Events of group {task} enabled by remote.
[2022-06-27 08:16:59,975: INFO/MainProcess] Received task: create_task[fe99293a-5909-4b52-adde-a2986c8516c7]  
[2022-06-27 08:18:40,025: INFO/ForkPoolWorker-3] Task create_task[fe99293a-5909-4b52-adde-a2986c8516c7] succeeded in 100.10413420700024s: True
[2022-06-27 10:48:17,498: CRITICAL/MainProcess] Unrecoverable error: ImproperlyConfigured('You need to install the redis library in order to use the Redis result store backend.')
Traceback (most recent call last):
  File "/usr/local/lib/python3.9/site-packages/kombu/utils/objects.py", line 42, in __get__
    return obj.__dict__[self.__name__]
KeyError: 'backend'

During handling of the above exception, another exception occurred:

Traceback (most recent call last):
  File "/usr/local/lib/python3.9/site-packages/celery/worker/worker.py", line 208, in start
    self.blueprint.start(self)
  File "/usr/local/lib/python3.9/site-packages/celery/bootsteps.py", line 115, in start
    self.on_start()
  File "/usr/local/lib/python3.9/site-packages/celery/apps/worker.py", line 140, in on_start
    self.emit_banner()
  File "/usr/local/lib/python3.9/site-packages/celery/apps/worker.py", line 155, in emit_banner
    ' \n', self.startup_info(artlines=not use_image))),
  File "/usr/local/lib/python3.9/site-packages/celery/apps/worker.py", line 218, in startup_info
    results=self.app.backend.as_uri(),
  File "/usr/local/lib/python3.9/site-packages/kombu/utils/objects.py", line 44, in __get__
    value = obj.__dict__[self.__name__] = self.__get(obj)
  File "/usr/local/lib/python3.9/site-packages/celery/app/base.py", line 1193, in backend
    return self._get_backend()
  File "/usr/local/lib/python3.9/site-packages/celery/app/base.py", line 911, in _get_backend
    return backend(app=self, url=url)
  File "/usr/local/lib/python3.9/site-packages/celery/backends/redis.py", line 210, in __init__
    raise ImproperlyConfigured(E_REDIS_MISSING.strip())
celery.exceptions.ImproperlyConfigured: You need to install the redis library in order to use the Redis result store backend.
[2022-06-27 10:50:58,704: CRITICAL/MainProcess] Unrecoverable error: ImproperlyConfigured('You need to install the redis library in order to use the Redis result store backend.')
Traceback (most recent call last):
  File "/usr/local/lib/python3.9/site-packages/kombu/utils/objects.py", line 42, in __get__
    return obj.__dict__[self.__name__]
KeyError: 'backend'

During handling of the above exception, another exception occurred:

Traceback (most recent call last):
  File "/usr/local/lib/python3.9/site-packages/celery/worker/worker.py", line 208, in start
    self.blueprint.start(self)
  File "/usr/local/lib/python3.9/site-packages/celery/bootsteps.py", line 115, in start
    self.on_start()
  File "/usr/local/lib/python3.9/site-packages/celery/apps/worker.py", line 140, in on_start
    self.emit_banner()
  File "/usr/local/lib/python3.9/site-packages/celery/apps/worker.py", line 155, in emit_banner
    ' \n', self.startup_info(artlines=not use_image))),
  File "/usr/local/lib/python3.9/site-packages/celery/apps/worker.py", line 218, in startup_info
    results=self.app.backend.as_uri(),
  File "/usr/local/lib/python3.9/site-packages/kombu/utils/objects.py", line 44, in __get__
    value = obj.__dict__[self.__name__] = self.__get(obj)
  File "/usr/local/lib/python3.9/site-packages/celery/app/base.py", line 1193, in backend
    return self._get_backend()
  File "/usr/local/lib/python3.9/site-packages/celery/app/base.py", line 911, in _get_backend
    return backend(app=self, url=url)
  File "/usr/local/lib/python3.9/site-packages/celery/backends/redis.py", line 210, in __init__
    raise ImproperlyConfigured(E_REDIS_MISSING.strip())
celery.exceptions.ImproperlyConfigured: You need to install the redis library in order to use the Redis result store backend.
[2022-06-27 10:51:36,506: CRITICAL/MainProcess] Unrecoverable error: ImproperlyConfigured('You need to install the redis library in order to use the Redis result store backend.')
Traceback (most recent call last):
  File "/usr/local/lib/python3.9/site-packages/kombu/utils/objects.py", line 42, in __get__
    return obj.__dict__[self.__name__]
KeyError: 'backend'

During handling of the above exception, another exception occurred:

Traceback (most recent call last):
  File "/usr/local/lib/python3.9/site-packages/celery/worker/worker.py", line 208, in start
    self.blueprint.start(self)
  File "/usr/local/lib/python3.9/site-packages/celery/bootsteps.py", line 115, in start
    self.on_start()
  File "/usr/local/lib/python3.9/site-packages/celery/apps/worker.py", line 140, in on_start
    self.emit_banner()
  File "/usr/local/lib/python3.9/site-packages/celery/apps/worker.py", line 155, in emit_banner
    ' \n', self.startup_info(artlines=not use_image))),
  File "/usr/local/lib/python3.9/site-packages/celery/apps/worker.py", line 218, in startup_info
    results=self.app.backend.as_uri(),
  File "/usr/local/lib/python3.9/site-packages/kombu/utils/objects.py", line 44, in __get__
    value = obj.__dict__[self.__name__] = self.__get(obj)
  File "/usr/local/lib/python3.9/site-packages/celery/app/base.py", line 1193, in backend
    return self._get_backend()
  File "/usr/local/lib/python3.9/site-packages/celery/app/base.py", line 911, in _get_backend
    return backend(app=self, url=url)
  File "/usr/local/lib/python3.9/site-packages/celery/backends/redis.py", line 210, in __init__
    raise ImproperlyConfigured(E_REDIS_MISSING.strip())
celery.exceptions.ImproperlyConfigured: You need to install the redis library in order to use the Redis result store backend.
[2022-06-27 10:55:38,926: CRITICAL/MainProcess] Unrecoverable error: ImproperlyConfigured('You need to install the redis library in order to use the Redis result store backend.')
Traceback (most recent call last):
  File "/usr/local/lib/python3.9/site-packages/kombu/utils/objects.py", line 42, in __get__
    return obj.__dict__[self.__name__]
KeyError: 'backend'

During handling of the above exception, another exception occurred:

Traceback (most recent call last):
  File "/usr/local/lib/python3.9/site-packages/celery/worker/worker.py", line 208, in start
    self.blueprint.start(self)
  File "/usr/local/lib/python3.9/site-packages/celery/bootsteps.py", line 115, in start
    self.on_start()
  File "/usr/local/lib/python3.9/site-packages/celery/apps/worker.py", line 140, in on_start
    self.emit_banner()
  File "/usr/local/lib/python3.9/site-packages/celery/apps/worker.py", line 155, in emit_banner
    ' \n', self.startup_info(artlines=not use_image))),
  File "/usr/local/lib/python3.9/site-packages/celery/apps/worker.py", line 218, in startup_info
    results=self.app.backend.as_uri(),
  File "/usr/local/lib/python3.9/site-packages/kombu/utils/objects.py", line 44, in __get__
    value = obj.__dict__[self.__name__] = self.__get(obj)
  File "/usr/local/lib/python3.9/site-packages/celery/app/base.py", line 1193, in backend
    return self._get_backend()
  File "/usr/local/lib/python3.9/site-packages/celery/app/base.py", line 911, in _get_backend
    return backend(app=self, url=url)
  File "/usr/local/lib/python3.9/site-packages/celery/backends/redis.py", line 210, in __init__
    raise ImproperlyConfigured(E_REDIS_MISSING.strip())
celery.exceptions.ImproperlyConfigured: You need to install the redis library in order to use the Redis result store backend.
[2022-06-27 10:58:23,989: INFO/MainProcess] Connected to amqp://guest:**@rabbitmq:5672//
[2022-06-27 10:58:24,001: INFO/MainProcess] mingle: searching for neighbors
[2022-06-27 10:58:25,033: INFO/MainProcess] mingle: all alone
[2022-06-27 10:58:25,066: INFO/MainProcess] celery@436f9d5140cd ready.
[2022-06-27 10:58:29,242: INFO/MainProcess] Events of group {task} enabled by remote.
[2022-06-27 11:01:45,578: INFO/MainProcess] Connected to amqp://guest:**@rabbitmq:5672//
[2022-06-27 11:01:45,590: INFO/MainProcess] mingle: searching for neighbors
[2022-06-27 11:01:46,617: INFO/MainProcess] mingle: all alone
[2022-06-27 11:01:46,621: INFO/MainProcess] celery@53971617411b ready.
[2022-06-27 11:01:50,770: INFO/MainProcess] Events of group {task} enabled by remote.
[2022-06-27 11:06:33,058: INFO/MainProcess] Connected to amqp://guest:**@rabbitmq:5672//
[2022-06-27 11:06:33,068: INFO/MainProcess] mingle: searching for neighbors
[2022-06-27 11:06:34,100: INFO/MainProcess] mingle: all alone
[2022-06-27 11:06:34,122: INFO/MainProcess] celery@7630b9e71968 ready.
[2022-06-27 11:06:38,325: INFO/MainProcess] Events of group {task} enabled by remote.
[2022-06-27 11:06:45,357: INFO/MainProcess] Received task: create_task[f1e4cd51-5d61-47da-9738-01a099ab2061]  
[2022-06-27 11:07:15,358: INFO/ForkPoolWorker-3] Task create_task[f1e4cd51-5d61-47da-9738-01a099ab2061] succeeded in 30.018590464s: True
[2022-06-27 11:12:42,483: INFO/MainProcess] Connected to amqp://guest:**@rabbitmq:5672//
[2022-06-27 11:12:42,494: INFO/MainProcess] mingle: searching for neighbors
[2022-06-27 11:12:43,537: INFO/MainProcess] mingle: all alone
[2022-06-27 11:12:43,561: INFO/MainProcess] celery@a8a9f8a5050c ready.
[2022-06-27 11:12:47,711: INFO/MainProcess] Events of group {task} enabled by remote.
[2022-06-27 11:13:09,412: INFO/MainProcess] Received task: create_task[b4b7ad44-8bad-4e8b-ada7-55ab94e311b8]  
[2022-06-27 11:13:09,450: INFO/ForkPoolWorker-3] Task create_task[b4b7ad44-8bad-4e8b-ada7-55ab94e311b8] succeeded in 0.0345954829999755s: True
